[2022-09-23 16:00:34,244: INFO: stage_01_prepare_data]: 
********************
[2022-09-23 16:00:34,245: INFO: stage_01_prepare_data]: >>>>> stage One started <<<<<
[2022-09-23 16:00:34,250: INFO: common]: yaml file: configs/config.yaml loaded successfully
[2022-09-23 16:00:34,254: INFO: common]: yaml file: params.yaml loaded successfully
[2022-09-23 16:00:35,673: ERROR: stage_01_prepare_data]: RESOURCE_DOES_NOT_EXIST: Run with id=9290d41be2da495b99b80eae6bab5e3b not found
Traceback (most recent call last):
  File "src/stage_01_prepare_data.py", line 63, in <module>
    main(config_path=parsed_args.config, params_path=parsed_args.params)
  File "src/stage_01_prepare_data.py", line 33, in main
    mlflow.log_param("split", split)
  File "D:\ALL_Python\AI_ops\PROJECTS\mlflow_NLP_simple\env\lib\site-packages\mlflow\tracking\fluent.py", line 542, in log_param
    run_id = _get_or_start_run().info.run_id
  File "D:\ALL_Python\AI_ops\PROJECTS\mlflow_NLP_simple\env\lib\site-packages\mlflow\tracking\fluent.py", line 1642, in _get_or_start_run
    return start_run()
  File "D:\ALL_Python\AI_ops\PROJECTS\mlflow_NLP_simple\env\lib\site-packages\mlflow\tracking\fluent.py", line 289, in start_run
    active_run_obj = client.get_run(existing_run_id)
  File "D:\ALL_Python\AI_ops\PROJECTS\mlflow_NLP_simple\env\lib\site-packages\mlflow\tracking\client.py", line 150, in get_run
    return self._tracking_client.get_run(run_id)
  File "D:\ALL_Python\AI_ops\PROJECTS\mlflow_NLP_simple\env\lib\site-packages\mlflow\tracking\_tracking_service\client.py", line 72, in get_run
    return self.store.get_run(run_id)
  File "D:\ALL_Python\AI_ops\PROJECTS\mlflow_NLP_simple\env\lib\site-packages\mlflow\store\tracking\rest_store.py", line 163, in get_run
    response_proto = self._call_endpoint(GetRun, req_body)
  File "D:\ALL_Python\AI_ops\PROJECTS\mlflow_NLP_simple\env\lib\site-packages\mlflow\store\tracking\rest_store.py", line 57, in _call_endpoint
    return call_endpoint(self.get_host_creds(), endpoint, method, json_body, response_proto)
  File "D:\ALL_Python\AI_ops\PROJECTS\mlflow_NLP_simple\env\lib\site-packages\mlflow\utils\rest_utils.py", line 274, in call_endpoint
    response = verify_rest_response(response, endpoint)
  File "D:\ALL_Python\AI_ops\PROJECTS\mlflow_NLP_simple\env\lib\site-packages\mlflow\utils\rest_utils.py", line 200, in verify_rest_response
    raise RestException(json.loads(response.text))
mlflow.exceptions.RestException: RESOURCE_DOES_NOT_EXIST: Run with id=9290d41be2da495b99b80eae6bab5e3b not found
[2022-09-23 16:05:52,674: INFO: stage_01_prepare_data]: 
********************
[2022-09-23 16:05:52,674: INFO: stage_01_prepare_data]: >>>>> stage One started <<<<<
[2022-09-23 16:05:52,680: INFO: common]: yaml file: configs/config.yaml loaded successfully
[2022-09-23 16:05:52,686: INFO: common]: yaml file: params.yaml loaded successfully
[2022-09-23 16:05:52,773: ERROR: stage_01_prepare_data]: RESOURCE_DOES_NOT_EXIST: Run with id=7285920226384676a1b4abee9db0f456 not found
Traceback (most recent call last):
  File "src/stage_01_prepare_data.py", line 65, in <module>
    main(config_path=parsed_args.config, params_path=parsed_args.params)
  File "src/stage_01_prepare_data.py", line 34, in main
    mlflow.log_param("split", split)
  File "D:\ALL_Python\AI_ops\PROJECTS\mlflow_NLP_simple\env\lib\site-packages\mlflow\tracking\fluent.py", line 542, in log_param
    run_id = _get_or_start_run().info.run_id
  File "D:\ALL_Python\AI_ops\PROJECTS\mlflow_NLP_simple\env\lib\site-packages\mlflow\tracking\fluent.py", line 1642, in _get_or_start_run
    return start_run()
  File "D:\ALL_Python\AI_ops\PROJECTS\mlflow_NLP_simple\env\lib\site-packages\mlflow\tracking\fluent.py", line 289, in start_run
    active_run_obj = client.get_run(existing_run_id)
  File "D:\ALL_Python\AI_ops\PROJECTS\mlflow_NLP_simple\env\lib\site-packages\mlflow\tracking\client.py", line 150, in get_run
    return self._tracking_client.get_run(run_id)
  File "D:\ALL_Python\AI_ops\PROJECTS\mlflow_NLP_simple\env\lib\site-packages\mlflow\tracking\_tracking_service\client.py", line 72, in get_run
    return self.store.get_run(run_id)
  File "D:\ALL_Python\AI_ops\PROJECTS\mlflow_NLP_simple\env\lib\site-packages\mlflow\store\tracking\rest_store.py", line 163, in get_run
    response_proto = self._call_endpoint(GetRun, req_body)
  File "D:\ALL_Python\AI_ops\PROJECTS\mlflow_NLP_simple\env\lib\site-packages\mlflow\store\tracking\rest_store.py", line 57, in _call_endpoint
    return call_endpoint(self.get_host_creds(), endpoint, method, json_body, response_proto)
  File "D:\ALL_Python\AI_ops\PROJECTS\mlflow_NLP_simple\env\lib\site-packages\mlflow\utils\rest_utils.py", line 274, in call_endpoint
    response = verify_rest_response(response, endpoint)
  File "D:\ALL_Python\AI_ops\PROJECTS\mlflow_NLP_simple\env\lib\site-packages\mlflow\utils\rest_utils.py", line 200, in verify_rest_response
    raise RestException(json.loads(response.text))
mlflow.exceptions.RestException: RESOURCE_DOES_NOT_EXIST: Run with id=7285920226384676a1b4abee9db0f456 not found
[2022-09-23 16:09:29,845: INFO: stage_01_prepare_data]: 
********************
[2022-09-23 16:09:29,845: INFO: stage_01_prepare_data]: >>>>> stage One started <<<<<
[2022-09-23 16:09:29,851: INFO: common]: yaml file: configs/config.yaml loaded successfully
[2022-09-23 16:09:29,854: INFO: common]: yaml file: params.yaml loaded successfully
[2022-09-23 16:09:29,921: ERROR: stage_01_prepare_data]: RESOURCE_DOES_NOT_EXIST: Run with id=0913b6e3f5fa449ca0e6ee59c79957f7 not found
Traceback (most recent call last):
  File "src/stage_01_prepare_data.py", line 66, in <module>
    main(config_path=parsed_args.config, params_path=parsed_args.params)
  File "src/stage_01_prepare_data.py", line 34, in main
    with mlflow.start_run():
  File "D:\ALL_Python\AI_ops\PROJECTS\mlflow_NLP_simple\env\lib\site-packages\mlflow\tracking\fluent.py", line 289, in start_run
    active_run_obj = client.get_run(existing_run_id)
  File "D:\ALL_Python\AI_ops\PROJECTS\mlflow_NLP_simple\env\lib\site-packages\mlflow\tracking\client.py", line 150, in get_run
    return self._tracking_client.get_run(run_id)
  File "D:\ALL_Python\AI_ops\PROJECTS\mlflow_NLP_simple\env\lib\site-packages\mlflow\tracking\_tracking_service\client.py", line 72, in get_run
    return self.store.get_run(run_id)
  File "D:\ALL_Python\AI_ops\PROJECTS\mlflow_NLP_simple\env\lib\site-packages\mlflow\store\tracking\rest_store.py", line 163, in get_run
    response_proto = self._call_endpoint(GetRun, req_body)
  File "D:\ALL_Python\AI_ops\PROJECTS\mlflow_NLP_simple\env\lib\site-packages\mlflow\store\tracking\rest_store.py", line 57, in _call_endpoint
    return call_endpoint(self.get_host_creds(), endpoint, method, json_body, response_proto)
  File "D:\ALL_Python\AI_ops\PROJECTS\mlflow_NLP_simple\env\lib\site-packages\mlflow\utils\rest_utils.py", line 274, in call_endpoint
    response = verify_rest_response(response, endpoint)
  File "D:\ALL_Python\AI_ops\PROJECTS\mlflow_NLP_simple\env\lib\site-packages\mlflow\utils\rest_utils.py", line 200, in verify_rest_response
    raise RestException(json.loads(response.text))
mlflow.exceptions.RestException: RESOURCE_DOES_NOT_EXIST: Run with id=0913b6e3f5fa449ca0e6ee59c79957f7 not found
[2022-09-23 16:19:52,927: INFO: stage_01_prepare_data]: 
********************
[2022-09-23 16:19:52,927: INFO: stage_01_prepare_data]: >>>>> stage One started <<<<<
[2022-09-23 16:19:52,931: INFO: common]: yaml file: configs/config.yaml loaded successfully
[2022-09-23 16:19:52,934: INFO: common]: yaml file: params.yaml loaded successfully
[2022-09-23 16:19:54,538: ERROR: stage_01_prepare_data]: RESOURCE_DOES_NOT_EXIST: Run with id=40db8532649d4e388c5263d61d4d2d56 not found
Traceback (most recent call last):
  File "src/stage_01_prepare_data.py", line 66, in <module>
    main(config_path=parsed_args.config, params_path=parsed_args.params)
  File "src/stage_01_prepare_data.py", line 35, in main
    mlflow.log_param("split", split)
  File "D:\ALL_Python\AI_ops\PROJECTS\mlflow_NLP_simple\env\lib\site-packages\mlflow\tracking\fluent.py", line 542, in log_param
    run_id = _get_or_start_run().info.run_id
  File "D:\ALL_Python\AI_ops\PROJECTS\mlflow_NLP_simple\env\lib\site-packages\mlflow\tracking\fluent.py", line 1642, in _get_or_start_run
    return start_run()
  File "D:\ALL_Python\AI_ops\PROJECTS\mlflow_NLP_simple\env\lib\site-packages\mlflow\tracking\fluent.py", line 289, in start_run
    active_run_obj = client.get_run(existing_run_id)
  File "D:\ALL_Python\AI_ops\PROJECTS\mlflow_NLP_simple\env\lib\site-packages\mlflow\tracking\client.py", line 150, in get_run
    return self._tracking_client.get_run(run_id)
  File "D:\ALL_Python\AI_ops\PROJECTS\mlflow_NLP_simple\env\lib\site-packages\mlflow\tracking\_tracking_service\client.py", line 72, in get_run
    return self.store.get_run(run_id)
  File "D:\ALL_Python\AI_ops\PROJECTS\mlflow_NLP_simple\env\lib\site-packages\mlflow\store\tracking\rest_store.py", line 163, in get_run
    response_proto = self._call_endpoint(GetRun, req_body)
  File "D:\ALL_Python\AI_ops\PROJECTS\mlflow_NLP_simple\env\lib\site-packages\mlflow\store\tracking\rest_store.py", line 57, in _call_endpoint
    return call_endpoint(self.get_host_creds(), endpoint, method, json_body, response_proto)
  File "D:\ALL_Python\AI_ops\PROJECTS\mlflow_NLP_simple\env\lib\site-packages\mlflow\utils\rest_utils.py", line 274, in call_endpoint
    response = verify_rest_response(response, endpoint)
  File "D:\ALL_Python\AI_ops\PROJECTS\mlflow_NLP_simple\env\lib\site-packages\mlflow\utils\rest_utils.py", line 200, in verify_rest_response
    raise RestException(json.loads(response.text))
mlflow.exceptions.RestException: RESOURCE_DOES_NOT_EXIST: Run with id=40db8532649d4e388c5263d61d4d2d56 not found
[2022-09-23 16:23:00,621: INFO: stage_01_prepare_data]: 
********************
[2022-09-23 16:23:00,621: INFO: stage_01_prepare_data]: >>>>> stage One started <<<<<
[2022-09-23 16:23:00,624: INFO: common]: yaml file: configs/config.yaml loaded successfully
[2022-09-23 16:23:00,627: INFO: common]: yaml file: params.yaml loaded successfully
[2022-09-23 16:23:00,778: ERROR: stage_01_prepare_data]: RESOURCE_DOES_NOT_EXIST: Run with id=c4bcfc54cf6b444797bd419dae1d94eb not found
Traceback (most recent call last):
  File "src/stage_01_prepare_data.py", line 66, in <module>
    main(config_path=parsed_args.config, params_path=parsed_args.params)
  File "src/stage_01_prepare_data.py", line 35, in main
    mlflow.log_param("split", split)
  File "D:\ALL_Python\AI_ops\PROJECTS\mlflow_NLP_simple\env\lib\site-packages\mlflow\tracking\fluent.py", line 542, in log_param
    run_id = _get_or_start_run().info.run_id
  File "D:\ALL_Python\AI_ops\PROJECTS\mlflow_NLP_simple\env\lib\site-packages\mlflow\tracking\fluent.py", line 1642, in _get_or_start_run
    return start_run()
  File "D:\ALL_Python\AI_ops\PROJECTS\mlflow_NLP_simple\env\lib\site-packages\mlflow\tracking\fluent.py", line 289, in start_run
    active_run_obj = client.get_run(existing_run_id)
  File "D:\ALL_Python\AI_ops\PROJECTS\mlflow_NLP_simple\env\lib\site-packages\mlflow\tracking\client.py", line 150, in get_run
    return self._tracking_client.get_run(run_id)
  File "D:\ALL_Python\AI_ops\PROJECTS\mlflow_NLP_simple\env\lib\site-packages\mlflow\tracking\_tracking_service\client.py", line 72, in get_run
    return self.store.get_run(run_id)
  File "D:\ALL_Python\AI_ops\PROJECTS\mlflow_NLP_simple\env\lib\site-packages\mlflow\store\tracking\rest_store.py", line 163, in get_run
    response_proto = self._call_endpoint(GetRun, req_body)
  File "D:\ALL_Python\AI_ops\PROJECTS\mlflow_NLP_simple\env\lib\site-packages\mlflow\store\tracking\rest_store.py", line 57, in _call_endpoint
    return call_endpoint(self.get_host_creds(), endpoint, method, json_body, response_proto)
  File "D:\ALL_Python\AI_ops\PROJECTS\mlflow_NLP_simple\env\lib\site-packages\mlflow\utils\rest_utils.py", line 274, in call_endpoint
    response = verify_rest_response(response, endpoint)
  File "D:\ALL_Python\AI_ops\PROJECTS\mlflow_NLP_simple\env\lib\site-packages\mlflow\utils\rest_utils.py", line 200, in verify_rest_response
    raise RestException(json.loads(response.text))
mlflow.exceptions.RestException: RESOURCE_DOES_NOT_EXIST: Run with id=c4bcfc54cf6b444797bd419dae1d94eb not found
[2022-09-23 16:29:48,361: INFO: stage_01_prepare_data]: 
********************
[2022-09-23 16:29:48,361: INFO: stage_01_prepare_data]: >>>>> stage One started <<<<<
[2022-09-23 16:29:48,370: INFO: common]: yaml file: configs/config.yaml loaded successfully
[2022-09-23 16:29:48,376: INFO: common]: yaml file: params.yaml loaded successfully
[2022-09-23 16:29:50,330: ERROR: stage_01_prepare_data]: RESOURCE_DOES_NOT_EXIST: Run with id=7c561672df834b1bb01c40f1040f865f not found
Traceback (most recent call last):
  File "src/stage_01_prepare_data.py", line 66, in <module>
    main(config_path=parsed_args.config, params_path=parsed_args.params)
  File "src/stage_01_prepare_data.py", line 35, in main
    mlflow.log_param("split", split)
  File "D:\ALL_Python\AI_ops\PROJECTS\mlflow_NLP_simple\env\lib\site-packages\mlflow\tracking\fluent.py", line 542, in log_param
    run_id = _get_or_start_run().info.run_id
  File "D:\ALL_Python\AI_ops\PROJECTS\mlflow_NLP_simple\env\lib\site-packages\mlflow\tracking\fluent.py", line 1642, in _get_or_start_run
    return start_run()
  File "D:\ALL_Python\AI_ops\PROJECTS\mlflow_NLP_simple\env\lib\site-packages\mlflow\tracking\fluent.py", line 289, in start_run
    active_run_obj = client.get_run(existing_run_id)
  File "D:\ALL_Python\AI_ops\PROJECTS\mlflow_NLP_simple\env\lib\site-packages\mlflow\tracking\client.py", line 150, in get_run
    return self._tracking_client.get_run(run_id)
  File "D:\ALL_Python\AI_ops\PROJECTS\mlflow_NLP_simple\env\lib\site-packages\mlflow\tracking\_tracking_service\client.py", line 72, in get_run
    return self.store.get_run(run_id)
  File "D:\ALL_Python\AI_ops\PROJECTS\mlflow_NLP_simple\env\lib\site-packages\mlflow\store\tracking\rest_store.py", line 163, in get_run
    response_proto = self._call_endpoint(GetRun, req_body)
  File "D:\ALL_Python\AI_ops\PROJECTS\mlflow_NLP_simple\env\lib\site-packages\mlflow\store\tracking\rest_store.py", line 57, in _call_endpoint
    return call_endpoint(self.get_host_creds(), endpoint, method, json_body, response_proto)
  File "D:\ALL_Python\AI_ops\PROJECTS\mlflow_NLP_simple\env\lib\site-packages\mlflow\utils\rest_utils.py", line 274, in call_endpoint
    response = verify_rest_response(response, endpoint)
  File "D:\ALL_Python\AI_ops\PROJECTS\mlflow_NLP_simple\env\lib\site-packages\mlflow\utils\rest_utils.py", line 200, in verify_rest_response
    raise RestException(json.loads(response.text))
mlflow.exceptions.RestException: RESOURCE_DOES_NOT_EXIST: Run with id=7c561672df834b1bb01c40f1040f865f not found
